Workbook

Sheet PART I - MODEL BUILD >>>

Sheet Financials from CIP
B3: Project Athena
B4: Quarterly and Annual Financial Statements
B5: ($s in 000s)
B7: Income Statement
D9: FY | E9: FY
D10: 2023 | E10: 2024
B11: Service Revenues | D11: 67988.162 | E11: 74320.332
B12: Parts & Other | D12: 10577.514 | E12: 16293.676
B13: Total Revenue | D13: =+SUM(D11:D12) -> 78565.676 | E13: =+SUM(E11:E12) -> 90614.008
B15: Labor | D15: 41584.93 | E15: 49665.089
B16: Materials | D16: 8321.468 | E16: 9548.864
B17: Other CoGS | D17: 1655.791 | E17: 2404.723
B19: Total Gross Profit | D19: =+D13-SUM(D15:D18) -> 27003.487 | E19: =+E13-SUM(E15:E18) -> 28995.332
B21: Total Gross Margin % | D21: =+D19/D$13 -> 0.34370591 | E21: =+E19/E$13 -> 0.3199873
B23: Payroll & Related Expenses | D23: 10567.613 | E23: 11023.057
B24: Rent & Occupancy | D24: 3246.147 | E24: 4150.1989
B25: Depreciation | D25: 1180.1621 | E25: 1161.7643
B26: Amortization | D26: 208.264 | E26: 237.952
B27: Interest | D27: 2224.955 | E27: 1472.763
B28: Other SG&A | D28: 366.155 | E28: 263.433
B29: Income Taxes | D29: 3201.039 | E29: 2809.107
B30: Total SG&A | D30: =+SUM(D23:D29) -> 20994.335 | E30: =+SUM(E23:E29) -> 21118.275
B32: Other Expense (Income) | D32: 147.371 | E32: 273.439
B34: Net Income | D34: =+D19-D30-D32 -> 5861.7809 | E34: =+E19-E30-E32 -> 7603.6178
B36: EBITDA, Unadjusted | D36: =+D34+D25+D27+D29+D26+D32 -> 12823.572 | E36: =+E34+E25+E27+E29+E26+E32 -> 13558.643
B39: Total Profit Margin % | D39: =D34/D$13 -> 0.074609947 | E39: =E34/E$13 -> 0.083912167
B40: Total EBITDA Margin % | D40: =D36/D$13 -> 0.16322105 | E40: =E36/E$13 -> 0.14963076
B42: Balance Sheet
D44: YE | E44: YE
D45: =+D10 -> 2023 | E45: =+D45+1 -> 2024
B46: Cash & Cash Equivalents | D46: 7105.652 | E46: 2957.992
B47: Accounts Receivable, Gross | D47: 17300.432 | E47: 22973.94
B48: Allowance for Doubtful Accounts | D48: -519.013 | E48: -689.218
B49: Inventory | D49: 804.901 | E49: 1161.057
B50: Prepaids & Other | D50: 269.784 | E50: 344.919
B51: Total Current Assets | D51: =+SUM(D46:D50) -> 24961.756 | E51: =+SUM(E46:E50) -> 26748.69
B53: PP&E, Net | D53: 54584.7 | E53: 55684.984
B54: Long-Term Intangible Assets | D54: 4378.482 | E54: 4504.37
B56: Total Assets | D56: =+SUM(D51:D55) -> 83924.938 | E56: =+SUM(E51:E55) -> 86938.044
B58: Accounts Payable | D58: 2805.817 | E58: 2360.71
...

Sheet Step 1
C2: Athena Modeling Exercise
C3: Step 1 - Historicals
J5: Black font = Calculation
C6: YELLOWS ARE FILLS | F6: SKIP FOR NOW | J6: Blue font = Hardcoded Input/Assumption
J7: Green font = Pulled from another Sheet
B8: x | C8: Income Statement | M8: Use the historical financial statements (Income Statement and Balance Sheet) to get started. Copy the financial statements as they appear from your research
F10: MRY | G10: MRY | H10: Fiscal Years Ending December 31,
C11: ($ in millions) | F11: =EOMONTH(G11,-12) -> 45291 | G11: 45657 | H11: =EOMONTH(G11,12) -> 46022 | I11: =EOMONTH(H11,12) -> 46387 | J11: =EOMONTH(I11,12) -> 46752 | K11: =EOMONTH(J11,12) -> 47118 | L11: =EOMONTH(K11,12) -> 47483
C13: Total Revenue
C14: COGS
C15: Gross Profit | F15: =F13-F14 -> 0 | G15: =G13-G14 -> 0
C16: Gross Margin (%) | F16: =IFERROR(F15/F$13,"N/M") -> N/M | G16: =IFERROR(G15/G$13,"N/M") -> N/M
C17: SG&A
C18: EBITDA | F18: =F15-F17 -> 0 | G18: =G15-G17 -> 0
C19: EBITDA Margin (%) | F19: =IFERROR(F18/F$13,"N/M") -> N/M | G19: =IFERROR(G18/G$13,"N/M") -> N/M
C20: Depreciation
C21: Amortization
C22: EBIT | F22: =F18-SUM(F20:F21) -> 0 | G22: =G18-SUM(G20:G21) -> 0
C23: Interest (Income) / Expense
C24: Revolver – Interest
C25: Revolver – Undrawn Commitment Fee
C26: =+C66 -> Term Loan A
C27: =+C67 -> Subordinated - Note 1
C28: =+C68 -> Subordinated - Note 2
C29: Interest (Income) / Expense
C30: Other (Income) / Expense
C31: Income Before Taxes | F31: =F22-F29-F30 -> 0 | G31: =G22-G29-G30 -> 0
C32: Provision for Tax
C33: Net Income | F33: =F31-F32 -> 0 | G33: =G31-G32 -> 0
C34: Profit Margin (%) | F34: =IFERROR(F33/F$13,"N/M") -> N/M | G34: =IFERROR(G33/G$13,"N/M") -> N/M
C36: Capital Expenditures
B40: x | C40: Balance Sheet
F42: MRY | G42: MRY | H42: Fiscal Years Ending December 31,
C43: ($ in millions) | F43: =EOMONTH(G43,-12) -> 45291 | G43: =G$11 -> 45657 | H43: =H$11 -> 46022 | I43: =I$11 -> 46387 | J43: =J$11 -> 46752 | K43: =K$11 -> 47118 | L43: =L$11 -> 47483
C45: Assets
C47: Cash and Equivalents
C48: Accounts Receivable, net
C49: Inventory
C50: Prepaids and Other Current Assets
C51: Total Current Assets | F51: =SUM(F47:F50) -> 0 | G51: =SUM(G47:G50) -> 0
...

Sheet Step 1 Answer Key
C2: Athena Modeling Exercise
C3: Step 1 - Historicals
J5: Black font = Calculation
C6: YELLOWS ARE FILLS | F6: SKIP FOR NOW | J6: Blue font = Hardcoded Input/Assumption
J7: Green font = Pulled from another Sheet
B8: x | C8: Income Statement | M8: Use the historical financial statements (Income Statement and Balance Sheet) to get started. Copy the financial statements as they appear from your research
F10: MRY | G10: MRY | H10: Fiscal Years Ending December 31,
C11: ($ in millions) | F11: =EOMONTH(G11,-12) -> 45291 | G11: 45657 | H11: =EOMONTH(G11,12) -> 46022 | I11: =EOMONTH(H11,12) -> 46387 | J11: =EOMONTH(I11,12) -> 46752 | K11: =EOMONTH(J11,12) -> 47118 | L11: =EOMONTH(K11,12) -> 47483
C13: Total Revenue | F13: ='Financials from CIP'!D13/1000 -> 78.565676 | G13: ='Financials from CIP'!E13/1000 -> 90.614008
C14: COGS | F14: =SUM('Financials from CIP'!D15:D17)/1000 -> 51.562189 | G14: =SUM('Financials from CIP'!E15:E17)/1000 -> 61.618676
C15: Gross Profit | F15: =F13-F14 -> 27.003487 | G15: =G13-G14 -> 28.995332
C16: Gross Margin (%) | F16: =IFERROR(F15/F$13,"N/M") -> 0.34370591 | G16: =IFERROR(G15/G$13,"N/M") -> 0.3199873
C17: SG&A | F17: =SUM('Financials from CIP'!D23:D24,'Financials from CIP'!D28)/1000 -> 14.179915 | G17: =SUM('Financials from CIP'!E23:E24,'Financials from CIP'!E28)/1000 -> 15.436689
C18: EBITDA | F18: =F15-F17 -> 12.823572 | G18: =G15-G17 -> 13.558643
C19: EBITDA Margin (%) | F19: =IFERROR(F18/F$13,"N/M") -> 0.16322105 | G19: =IFERROR(G18/G$13,"N/M") -> 0.14963076
C20: Depreciation | F20: ='Financials from CIP'!D25/1000 -> 1.1801621 | G20: ='Financials from CIP'!E25/1000 -> 1.1617643
C21: Amortization | F21: ='Financials from CIP'!D26/1000 -> 0.208264 | G21: ='Financials from CIP'!E26/1000 -> 0.237952
C22: EBIT | F22: =F18-SUM(F20:F21) -> 11.435146 | G22: =G18-SUM(G20:G21) -> 12.158927
C23: Interest (Income) / Expense
C24: Revolver – Interest
C25: Revolver – Undrawn Commitment Fee
C26: =+C66 -> Term Loan A
C27: =+C67 -> Subordinated - Note 1
C28: =+C68 -> Subordinated - Note 2
C29: Interest (Income) / Expense | F29: ='Financials from CIP'!D27/1000 -> 2.224955 | G29: ='Financials from CIP'!E27/1000 -> 1.472763
C30: Other (Income) / Expense | F30: ='Financials from CIP'!D32/1000 -> 0.147371 | G30: ='Financials from CIP'!E32/1000 -> 0.273439
C31: Income Before Taxes | F31: =F22-F29-F30 -> 9.0628199 | G31: =G22-G29-G30 -> 10.412725
C32: Provision for Tax | F32: ='Financials from CIP'!D29/1000 -> 3.201039 | G32: ='Financials from CIP'!E29/1000 -> 2.809107
C33: Net Income | F33: =F31-F32 -> 5.8617809 | G33: =G31-G32 -> 7.6036178
C34: Profit Margin (%) | F34: =IFERROR(F33/F$13,"N/M") -> 0.074609947 | G34: =IFERROR(G33/G$13,"N/M") -> 0.083912167
C36: Capital Expenditures
B40: x | C40: Balance Sheet
F42: MRY | G42: MRY | H42: Fiscal Years Ending December 31,
C43: ($ in millions) | F43: =EOMONTH(G43,-12) -> 45291 | G43: =G$11 -> 45657 | H43: =H$11 -> 46022 | I43: =I$11 -> 46387 | J43: =J$11 -> 46752 | K43: =K$11 -> 47118 | L43: =L$11 -> 47483
C45: Assets
C47: Cash and Equivalents | F47: ='Financials from CIP'!D46/1000 -> 7.105652 | G47: ='Financials from CIP'!E46/1000 -> 2.957992
C48: Accounts Receivable, net | F48: =SUM('Financials from CIP'!D47:D48)/1000 -> 16.781419 | G48: =SUM('Financials from CIP'!E47:E48)/1000 -> 22.284722
C49: Inventory | F49: ='Financials from CIP'!D49/1000 -> 0.804901 | G49: ='Financials from CIP'!E49/1000 -> 1.161057
C50: Prepaids and Other Current Assets | F50: ='Financials from CIP'!D50/1000 -> 0.269784 | G50: ='Financials from CIP'!E50/1000 -> 0.344919
C51: Total Current Assets | F51: =SUM(F47:F50) -> 24.961756 | G51: =SUM(G47:G50) -> 26.74869
...

Sheet Step 2
C2: Athena Modeling Exercise
C3: Step 2 - Begin Projecting the Income Statement
J5: Black font = Calculation
C6: YELLOWS ARE FILLS | F6: SKIP FOR NOW | J6: Blue font = Hardcoded Input/Assumption
J7: Green font = Pulled from another Sheet
B8: x | C8: Income Statement
F10: MRY | G10: MRY | H10: Fiscal Years Ending December 31,
C11: ($ in millions) | F11: =EOMONTH(G11,-12) -> 45291 | G11: 45657 | H11: =EOMONTH(G11,12) -> 46022 | I11: =EOMONTH(H11,12) -> 46387 | J11: =EOMONTH(I11,12) -> 46752 | K11: =EOMONTH(J11,12) -> 47118 | L11: =EOMONTH(K11,12) -> 47483
C13: Total Revenue | F13: ='Financials from CIP'!D13/1000 -> 78.565676 | G13: ='Financials from CIP'!E13/1000 -> 90.614008 | M13: Revenue is grown year-over-year. Project total revenue based on the growth rate assumption below and the prior period revenue (line 41)
C14: COGS | F14: =SUM('Financials from CIP'!D15:D17)/1000 -> 51.562189 | G14: =SUM('Financials from CIP'!E15:E17)/1000 -> 61.618676 | M14: CoGS typically fluctuates with Revenue - it is the cost of the goods and services we sell. We call this a "Variable Cost." As such, project as a % of Sales based on the performance driver below - that way CoGS moves with Revenue
C15: Gross Profit | F15: =F13-F14 -> 27.003487 | G15: =G13-G14 -> 28.995332 | H15: =H13-H14 -> 0 | I15: =I13-I14 -> 0 | J15: =J13-J14 -> 0 | K15: =K13-K14 -> 0 | L15: =L13-L14 -> 0
C16: Gross Margin (%) | F16: =IFERROR(F15/F$13,"N/M") -> 0.34370591 | G16: =IFERROR(G15/G$13,"N/M") -> 0.3199873 | H16: =IFERROR(H15/H$13,"N/M") -> N/M | I16: =IFERROR(I15/I$13,"N/M") -> N/M | J16: =IFERROR(J15/J$13,"N/M") -> N/M | K16: =IFERROR(K15/K$13,"N/M") -> N/M | L16: =IFERROR(L15/L$13,"N/M") -> N/M | M16: Calculate Gross Profit Margin (Gross Profit / Total Revenue)
C17: SG&A | F17: =SUM('Financials from CIP'!D23:D24,'Financials from CIP'!D28)/1000 -> 14.179915 | G17: =SUM('Financials from CIP'!E23:E24,'Financials from CIP'!E28)/1000 -> 15.436689 | M17: SG&A typically has a part that is fixed (cost that does not fluctuate with revenue - like Rent) and a part that is Variable Cost. When I look at what the components of SG&A are using information from the 'Financials from CIP' tab, I see the majority of it is in Payroll & Related Expense - something that is most likely Variable. For simplicity sake, let's project SG&A in the business to be Variable. As such, project as a % of Sales based on the performance driver below
C18: EBITDA | F18: =F15-F17 -> 12.823572 | G18: =G15-G17 -> 13.558643 | H18: =H15-H17 -> 0 | I18: =I15-I17 -> 0 | J18: =J15-J17 -> 0 | K18: =K15-K17 -> 0 | L18: =L15-L17 -> 0
C19: EBITDA Margin (%) | F19: =IFERROR(F18/F$13,"N/M") -> 0.16322105 | G19: =IFERROR(G18/G$13,"N/M") -> 0.14963076 | H19: =IFERROR(H18/H$13,"N/M") -> N/M | I19: =IFERROR(I18/I$13,"N/M") -> N/M | J19: =IFERROR(J18/J$13,"N/M") -> N/M | K19: =IFERROR(K18/K$13,"N/M") -> N/M | L19: =IFERROR(L18/L$13,"N/M") -> N/M | M19: Calculate EBITDA Margin (EBITDA / Total Revenue)
C20: Depreciation | F20: ='Financials from CIP'!D25/1000 -> 1.1801621 | G20: ='Financials from CIP'!E25/1000 -> 1.1617643 | M20: See the schedule, below. Link total Depreciation per year from the schedule to here. Follow the Depreciation schedule instructions carefully
C21: Amortization | F21: ='Financials from CIP'!D26/1000 -> 0.208264 | G21: ='Financials from CIP'!E26/1000 -> 0.237952 | M21: Amortization Expense reduces Other Intangibles Assets on the Balance sheet. It is similar to Depreciation but for Assets that are not physical (like a copyright). For simplicity sake, let's hold the 2024 amount consistent per year going forward but be careful to not to amortize more than the Balance of the Other Intangible Assets in any given year. We will revisit this calculation to ensure its working properly in a later step
C22: EBIT | F22: =F18-SUM(F20:F21) -> 11.435146 | G22: =G18-SUM(G20:G21) -> 12.158927 | H22: =H18-SUM(H20:H21) -> 0 | I22: =I18-SUM(I20:I21) -> 0 | J22: =J18-SUM(J20:J21) -> 0 | K22: =K18-SUM(K20:K21) -> 0 | L22: =L18-SUM(L20:L21) -> 0
C23: Interest (Income) / Expense
C24: Revolver – Interest
C25: Revolver – Undrawn Commitment Fee
C26: =+C79 -> Term Loan A
C27: =+C80 -> Subordinated - Note 1
C28: =+C81 -> Subordinated - Note 2
C29: Interest (Income) / Expense | F29: ='Financials from CIP'!D27/1000 -> 2.224955 | G29: ='Financials from CIP'!E27/1000 -> 1.472763 | H29: =SUM(H24:H28) -> 0 | I29: =SUM(I24:I28) -> 0 | J29: =SUM(J24:J28) -> 0 | K29: =SUM(K24:K28) -> 0 | L29: =SUM(L24:L28) -> 0
C30: Other (Income) / Expense | F30: ='Financials from CIP'!D32/1000 -> 0.147371 | G30: ='Financials from CIP'!E32/1000 -> 0.273439 | M30: This is very low in 2023 and 2024. Let's assume it stays zero going forward
C31: Income Before Taxes | F31: =F22-F29-F30 -> 9.0628199 | G31: =G22-G29-G30 -> 10.412725 | H31: =H22-H29-H30 -> 0 | I31: =I22-I29-I30 -> 0 | J31: =J22-J29-J30 -> 0 | K31: =K22-K29-K30 -> 0 | L31: =L22-L29-L30 -> 0
C32: Provision for Tax | F32: ='Financials from CIP'!D29/1000 -> 3.201039 | G32: ='Financials from CIP'!E29/1000 -> 2.809107 | M32: Calculate tax expense based on the tax rate below
C33: Net Income | F33: =F31-F32 -> 5.8617809 | G33: =G31-G32 -> 7.6036178 | H33: =H31-H32 -> 0 | I33: =I31-I32 -> 0 | J33: =J31-J32 -> 0 | K33: =K31-K32 -> 0 | L33: =L31-L32 -> 0
C34: Profit Margin (%) | F34: =IFERROR(F33/F$13,"N/M") -> 0.074609947 | G34: =IFERROR(G33/G$13,"N/M") -> 0.083912167 | H34: =IFERROR(H33/H$13,"N/M") -> N/M | I34: =IFERROR(I33/I$13,"N/M") -> N/M | J34: =IFERROR(J33/J$13,"N/M") -> N/M | K34: =IFERROR(K33/K$13,"N/M") -> N/M | L34: =IFERROR(L33/L$13,"N/M") -> N/M
C36: Capital Expenditures
C39: Key Performance Metrics & Drivers
C41: Sales Growth (%) | M41: Round your 2024 growth rate to the nearest percent and use that for 2025 and 2026, reducing it by 3% per year thereafter
C43: COGS / Sales (%) | M43: Divide by sales to get the % in 2023 and 2024. Use an average as your assumption and hold constant going forward
C44: SG&A / Sales (%) | M44: Same as above
C46: Tax Rate (%) | M46: Round the 2024 tax rate to the nearest % and use that going forward
C48: Capex / Sales (%)
B53: x | C53: Balance Sheet
F55: MRY | G55: MRY | H55: Fiscal Years Ending December 31,
C56: ($ in millions) | F56: =EOMONTH(G56,-12) -> 45291 | G56: =G$11 -> 45657 | H56: =H$11 -> 46022 | I56: =I$11 -> 46387 | J56: =J$11 -> 46752 | K56: =K$11 -> 47118 | L56: =L$11 -> 47483
...
